<?xml version="1.0"?>

<robot name = "kuka-iiwa-14">

    <link name = "base_link">
        <visual>
            <origin rpy="0.0 0.0 0.0" xyz="0.0 0.0 0.0"/>
            <geometry>
                <mesh filename = "package://kuka-iiwa-14_description/meshes/link_0.dae" scale = "1.0 1.0 1.0"/>
            </geometry>
        </visual>
    </link>

    <!-- Joint 1: Base to Link 1 - Rotates around Z -->
    <joint name="base_to_link1" type="revolute">
        <origin xyz="0.0 0.0 0.1575"  rpy="0.0 0.0 0.0"/>
        <parent link="base_link"/>
        <child link="link_1"/>
        <axis xyz="0.0 0.0 1.0"/>
        <limit lower="-2.967" upper="2.967" effort="320.0" velocity="1.483"/>
    </joint>

    <link name = "link_1">
        <visual>
        <origin rpy="0.0 0.0 0.0" xyz ="0.0 0.0 0.0"/>
            <geometry>
                <mesh filename = "package://kuka-iiwa-14_description/meshes/link_1.dae" scale = "1.0 1.0 1.0"/>
            </geometry>
        </visual>
    </link>

    <!-- Joint 2: Link 1 to Link 2 - Rotates around Y -->
    <joint name="link1_to_link2" type="revolute">
        <origin xyz="0.0 0.0 0.2025"  rpy="0.0 0.0 0.0"/>
        <parent link="link_1"/>
        <child link="link_2"/>
        <axis xyz="0.0 1.0 0.0"/>
        <limit lower="-2.094" upper="2.094" effort="320.0" velocity="1.483"/>
    </joint>

    <link name = "link_2">
        <visual>
        <origin rpy="0.0 0.0 0.0" xyz ="0.0 0.0 0.0"/>
            <geometry>
                <mesh filename = "package://kuka-iiwa-14_description/meshes/link_2.dae" scale = "1.0 1.0 1.0"/>
            </geometry>
        </visual>
    </link>

    <!-- Joint 3: Link 2 to Link 3 - Rotates around Z -->
     <joint name="link2_to_link3" type="revolute">
        <origin xyz="0.0 0.0 0.2045"  rpy="0.0 0.0 0.0"/>
        <parent link="link_2"/>
        <child link="link_3"/>
        <axis xyz="0.0 0.0 1.0"/>
        <limit lower="-2.967" upper="2.967" effort="176.0" velocity="1.745"/>
    </joint>

    <link name = "link_3">
        <visual>
        <origin rpy="0.0 0.0 0.0" xyz ="0.0 0.0 0.0"/>
            <geometry>
                <mesh filename = "package://kuka-iiwa-14_description/meshes/link_3.dae" scale = "1.0 1.0 1.0"/>
            </geometry>
        </visual>
    </link>

    <!-- Joint 4: Link 3 to Link 4 - Rotates around -Y -->
    <joint name="link3_to_link4" type="revolute">
        <origin xyz="0.0 0.0 0.2155"  rpy="0.0 0.0 0.0"/>
        <parent link="link_3"/>
        <child link="link_4"/>
        <axis xyz="0.0 -1.0 0.0"/>
        <limit lower="-2.094" upper="2.094" effort="176.0" velocity="1.308"/>
    </joint>

    <link name = "link_4">
        <visual>
        <origin rpy="0.0 0.0 0.0" xyz ="0.0 0.0 0.0"/>
            <geometry>
                <mesh filename = "package://kuka-iiwa-14_description/meshes/link_4.dae" scale = "1.0 1.0 1.0"/>
            </geometry>
        </visual>
    </link>

    <!-- Joint 5: Link 4 to Link 5 - Rotates around Z -->
    <joint name="link4_to_link5" type="revolute">
        <origin xyz="0.0 0.0 0.1845"  rpy="0.0 0.0 0.0"/>
        <parent link="link_4"/>
        <child link="link_5"/>
        <axis xyz="0.0 0.0 1.0"/>
        <limit lower="-2.967" upper="2.967" effort="110.0" velocity="2.268"/>
    </joint>

    <link name = "link_5">
        <visual>
        <origin rpy="0.0 0.0 0.0" xyz ="0.0 0.0 0.0"/>
            <geometry>
                <mesh filename = "package://kuka-iiwa-14_description/meshes/link_5.dae" scale = "1.0 1.0 1.0"/>
            </geometry>
        </visual>
    </link>

    <!-- Joint 6: Link 5 to Link 6 - Rotates around Y -->
    <joint name="link5_to_link6" type="revolute">
        <origin xyz="0.0 0.0 0.2155"  rpy="0.0 0.0 0.0"/>
        <parent link="link_5"/>
        <child link="link_6"/>
        <axis xyz="0.0 1.0 0.0"/>
        <limit lower="-2.094" upper="2.094" effort="40.0" velocity="2.356"/>
    </joint>

    <link name = "link_6">
        <visual>
        <origin rpy="0.0 0.0 0.0" xyz ="0.0 0.0 0.0"/>
            <geometry>
                <mesh filename = "package://kuka-iiwa-14_description/meshes/link_6.dae" scale = "1.0 1.0 1.0"/>
            </geometry>
        </visual>
    </link>

    <!-- Joint 7: Link 6 to Link 7 - Rotates around Z -->
    <joint name="link6_to_link7" type="revolute">
        <origin xyz="0.0 0.0 0.081"  rpy="0.0 0.0 0.0"/>
        <parent link="link_6"/>
        <child link="link_7"/>
        <axis xyz="0.0 0.0 1.0"/>
        <limit lower="-3.054" upper="3.054" effort="40.0" velocity="2.356"/>
    </joint>

    <link name = "link_7">
        <visual>
        <origin rpy="0.0 0.0 0.0" xyz ="0.0 0.0 0.0"/>
            <geometry>
                <mesh filename = "package://kuka-iiwa-14_description/meshes/link_7.dae" scale = "1.0 1.0 1.0"/>
            </geometry>
        </visual>
    </link>
    
</robot>