<?xml version="1.0"?>

<robot name = "kuka-iiwa-14">

    <link name = "base_link">
        <visual>
            <origin rpy="0.0 0.0 0.0" xyz="0.0 0.0 0.0"/>
            <geometry>
                <mesh filename = "package://kuka-iiwa-14_description/meshes/link_0.dae" scale = "1.0 1.0 1.0"/>
            </geometry>
        </visual>
    </link>

    <joint name="base_to_link1" type="revolute">
        <origin xyz="0.0 0.0 0.0"  rpy="0.0 0.0 0.0"/>
        <parent link="base_link"/>
        <child link="link_1"/>
        <axis xyz="0.0 0.0 1.0"/>
        <limit lower="-2.967" upper="2.967" effort="10.0" velocity="1.0"/>
    </joint>

    <link name = "link_1">
        <visual>
        <origin rpy="0.0 0.0 0.0" xyz ="0.0 0.0 0.0"/>
            <geometry>
                <mesh filename = "package://kuka-iiwa-14_description/meshes/link_1.dae" scale = "1.0 1.0 1.0"/>
            </geometry>
        </visual>
    </link>

    <joint name="link1_to_link2" type="revolute">
        <origin xyz="0.0 0.0 0.0"  rpy="0.0 0.0 0.0"/>
        <parent link="link_1"/>
        <child link="link_2"/>
        <axis xyz="1.0 0.0 0.0"/>
        <limit lower="-2.967" upper="2.967" effort="10.0" velocity="1.0"/>
    </joint>

    <link name = "link_2">
        <visual>
        <origin rpy="0.0 0.0 0.0" xyz ="0.0 0.0 0.0"/>
            <geometry>
                <mesh filename = "package://kuka-iiwa-14_description/meshes/link_2.dae" scale = "1.0 1.0 1.0"/>
            </geometry>
        </visual>
    </link>

     <joint name="link2_to_link3" type="revolute">
        <origin xyz="0.0 0.0 0.0"  rpy="0.0 0.0 0.0"/>
        <parent link="link_2"/>
        <child link="link_3"/>
        <axis xyz="0.0 0.0 1.0"/>
        <limit lower="-2.967" upper="2.967" effort="10.0" velocity="1.0"/>
    </joint>

    <link name = "link_3">
        <visual>
        <origin rpy="0.0 0.0 0.0" xyz ="0.0 0.0 0.0"/>
            <geometry>
                <mesh filename = "package://kuka-iiwa-14_description/meshes/link_3.dae" scale = "1.0 1.0 1.0"/>
            </geometry>
        </visual>
    </link>

    <joint name="link3_to_link4" type="revolute">
        <origin xyz="0.0 0.0 0.0"  rpy="0.0 0.0 0.0"/>
        <parent link="link_3"/>
        <child link="link_4"/>
        <axis xyz="1.0 0.0 0.0"/>
        <limit lower="-2.967" upper="2.967" effort="10.0" velocity="1.0"/>
    </joint>

    <link name = "link_4">
        <visual>
        <origin rpy="0.0 0.0 0.0" xyz ="0.0 0.0 0.0"/>
            <geometry>
                <mesh filename = "package://kuka-iiwa-14_description/meshes/link_4.dae" scale = "1.0 1.0 1.0"/>
            </geometry>
        </visual>
    </link>

    <joint name="link4_to_link5" type="revolute">
        <origin xyz="0.0 0.0 0.0"  rpy="0.0 0.0 0.0"/>
        <parent link="link_4"/>
        <child link="link_5"/>
        <axis xyz="0.0 0.0 1.0"/>
        <limit lower="-2.967" upper="2.967" effort="10.0" velocity="1.0"/>
    </joint>

    <link name = "link_5">
        <visual>
        <origin rpy="0.0 0.0 0.0" xyz ="0.0 0.0 0.0"/>
            <geometry>
                <mesh filename = "package://kuka-iiwa-14_description/meshes/link_5.dae" scale = "1.0 1.0 1.0"/>
            </geometry>
        </visual>
    </link>

    <joint name="link5_to_link6" type="revolute">
        <origin xyz="0.0 0.0 0.0"  rpy="0.0 0.0 0.0"/>
        <parent link="link_5"/>
        <child link="link_6"/>
        <axis xyz="1.0 0.0 0.0"/>
        <limit lower="-2.967" upper="2.967" effort="10.0" velocity="1.0"/>
    </joint>

    <link name = "link_6">
        <visual>
        <origin rpy="0.0 0.0 0.0" xyz ="0.0 0.0 0.0"/>
            <geometry>
                <mesh filename = "package://kuka-iiwa-14_description/meshes/link_6.dae" scale = "1.0 1.0 1.0"/>
            </geometry>
        </visual>
    </link>

    <joint name="link6_to_link7" type="revolute">
        <origin xyz="0.0 0.0 0.0"  rpy="0.0 0.0 0.0"/>
        <parent link="link_6"/>
        <child link="link_7"/>
        <axis xyz="0.0 0.0 1.0"/>
        <limit lower="-2.967" upper="2.967" effort="10.0" velocity="1.0"/>
    </joint>

    <link name = "link_7">
        <visual>
        <origin rpy="0.0 0.0 0.0" xyz ="0.0 0.0 0.0"/>
            <geometry>
                <mesh filename = "package://kuka-iiwa-14_description/meshes/link_7.dae" scale = "1.0 1.0 1.0"/>
            </geometry>
        </visual>
    </link>
    
</robot>